[2025-03-19T03:54:33.854+0000] {local_task_job_runner.py:123} INFO - ::group::Pre task execution logs
[2025-03-19T03:54:33.881+0000] {taskinstance.py:2614} INFO - Dependencies all met for dep_context=non-requeueable deps ti=<TaskInstance: pyspark_etl_pipeline.bronze_ingestion manual__2025-03-18T19:18:51.027148+00:00 [queued]>
[2025-03-19T03:54:33.893+0000] {taskinstance.py:2614} INFO - Dependencies all met for dep_context=requeueable deps ti=<TaskInstance: pyspark_etl_pipeline.bronze_ingestion manual__2025-03-18T19:18:51.027148+00:00 [queued]>
[2025-03-19T03:54:33.894+0000] {taskinstance.py:2867} INFO - Starting attempt 7 of 7
[2025-03-19T03:54:33.912+0000] {taskinstance.py:2890} INFO - Executing <Task(BashOperator): bronze_ingestion> on 2025-03-18 19:18:51.027148+00:00
[2025-03-19T03:54:33.922+0000] {standard_task_runner.py:104} INFO - Running: ['***', 'tasks', 'run', 'pyspark_etl_pipeline', 'bronze_ingestion', 'manual__2025-03-18T19:18:51.027148+00:00', '--job-id', '82', '--raw', '--subdir', 'DAGS_FOLDER/dag_pipeline.py', '--cfg-path', '/tmp/tmplfhtzmb0']
[2025-03-19T03:54:33.926+0000] {standard_task_runner.py:105} INFO - Job 82: Subtask bronze_ingestion
[2025-03-19T03:54:33.928+0000] {logging_mixin.py:190} WARNING - /home/***/.local/lib/python3.12/site-packages/***/task/task_runner/standard_task_runner.py:70 DeprecationWarning: This process (pid=419) is multi-threaded, use of fork() may lead to deadlocks in the child.
[2025-03-19T03:54:33.929+0000] {standard_task_runner.py:72} INFO - Started process 420 to run task
[2025-03-19T03:54:33.977+0000] {task_command.py:467} INFO - Running <TaskInstance: pyspark_etl_pipeline.bronze_ingestion manual__2025-03-18T19:18:51.027148+00:00 [running]> on host dac4e97ffcdb
[2025-03-19T03:54:34.064+0000] {taskinstance.py:3134} INFO - Exporting env vars: AIRFLOW_CTX_DAG_OWNER='***' AIRFLOW_CTX_DAG_ID='pyspark_etl_pipeline' AIRFLOW_CTX_TASK_ID='bronze_ingestion' AIRFLOW_CTX_EXECUTION_DATE='2025-03-18T19:18:51.027148+00:00' AIRFLOW_CTX_TRY_NUMBER='7' AIRFLOW_CTX_DAG_RUN_ID='manual__2025-03-18T19:18:51.027148+00:00'
[2025-03-19T03:54:34.065+0000] {taskinstance.py:732} INFO - ::endgroup::
[2025-03-19T03:54:34.079+0000] {subprocess.py:78} INFO - Tmp dir root location: /tmp
[2025-03-19T03:54:34.080+0000] {subprocess.py:88} INFO - Running command: ['/usr/bin/bash', '-c', 'spark-submit --master local /opt/***/dags/bronze_ingestion.py']
[2025-03-19T03:54:34.087+0000] {subprocess.py:99} INFO - Output:
[2025-03-19T03:54:34.089+0000] {subprocess.py:106} INFO - /usr/bin/bash: line 1: spark-submit: command not found
[2025-03-19T03:54:34.090+0000] {subprocess.py:110} INFO - Command exited with return code 127
[2025-03-19T03:54:34.101+0000] {taskinstance.py:3313} ERROR - Task failed with exception
Traceback (most recent call last):
  File "/home/airflow/.local/lib/python3.12/site-packages/airflow/models/taskinstance.py", line 768, in _execute_task
    result = _execute_callable(context=context, **execute_callable_kwargs)
             ^^^^^^^^^^^^^^^^^^^^^^^^^^^^^^^^^^^^^^^^^^^^^^^^^^^^^^^^^^^^^
  File "/home/airflow/.local/lib/python3.12/site-packages/airflow/models/taskinstance.py", line 734, in _execute_callable
    return ExecutionCallableRunner(
           ^^^^^^^^^^^^^^^^^^^^^^^^
  File "/home/airflow/.local/lib/python3.12/site-packages/airflow/utils/operator_helpers.py", line 252, in run
    return self.func(*args, **kwargs)
           ^^^^^^^^^^^^^^^^^^^^^^^^^^
  File "/home/airflow/.local/lib/python3.12/site-packages/airflow/models/baseoperator.py", line 424, in wrapper
    return func(self, *args, **kwargs)
           ^^^^^^^^^^^^^^^^^^^^^^^^^^^
  File "/home/airflow/.local/lib/python3.12/site-packages/airflow/operators/bash.py", line 276, in execute
    raise AirflowException(
airflow.exceptions.AirflowException: Bash command failed. The command returned a non-zero exit code 127.
[2025-03-19T03:54:34.106+0000] {taskinstance.py:1226} INFO - Marking task as FAILED. dag_id=pyspark_etl_pipeline, task_id=bronze_ingestion, run_id=manual__2025-03-18T19:18:51.027148+00:00, execution_date=20250318T191851, start_date=20250319T035433, end_date=20250319T035434
[2025-03-19T03:54:34.106+0000] {taskinstance.py:1564} INFO - Executing callback at index 0: notify_failure
[2025-03-19T03:54:34.119+0000] {logging_mixin.py:190} WARNING - /home/***/.local/lib/python3.12/site-packages/***/utils/email.py:155 RemovedInAirflow3Warning: Fetching SMTP credentials from configuration variables will be deprecated in a future release. Please set credentials using a connection instead.
[2025-03-19T03:54:34.120+0000] {email.py:272} INFO - Email alerting: attempt 1
[2025-03-19T03:54:38.204+0000] {taskinstance.py:1568} ERROR - Error in callback at index 0: notify_failure
Traceback (most recent call last):
  File "/home/airflow/.local/lib/python3.12/site-packages/airflow/models/taskinstance.py", line 274, in _run_raw_task
    TaskInstance._execute_task_with_callbacks(
  File "/home/airflow/.local/lib/python3.12/site-packages/airflow/models/taskinstance.py", line 3161, in _execute_task_with_callbacks
    result = self._execute_task(context, task_orig)
             ^^^^^^^^^^^^^^^^^^^^^^^^^^^^^^^^^^^^^^
  File "/home/airflow/.local/lib/python3.12/site-packages/airflow/models/taskinstance.py", line 3185, in _execute_task
    return _execute_task(self, context, task_orig)
           ^^^^^^^^^^^^^^^^^^^^^^^^^^^^^^^^^^^^^^^
  File "/home/airflow/.local/lib/python3.12/site-packages/airflow/models/taskinstance.py", line 768, in _execute_task
    result = _execute_callable(context=context, **execute_callable_kwargs)
             ^^^^^^^^^^^^^^^^^^^^^^^^^^^^^^^^^^^^^^^^^^^^^^^^^^^^^^^^^^^^^
  File "/home/airflow/.local/lib/python3.12/site-packages/airflow/models/taskinstance.py", line 734, in _execute_callable
    return ExecutionCallableRunner(
           ^^^^^^^^^^^^^^^^^^^^^^^^
  File "/home/airflow/.local/lib/python3.12/site-packages/airflow/utils/operator_helpers.py", line 252, in run
    return self.func(*args, **kwargs)
           ^^^^^^^^^^^^^^^^^^^^^^^^^^
  File "/home/airflow/.local/lib/python3.12/site-packages/airflow/models/baseoperator.py", line 424, in wrapper
    return func(self, *args, **kwargs)
           ^^^^^^^^^^^^^^^^^^^^^^^^^^^
  File "/home/airflow/.local/lib/python3.12/site-packages/airflow/operators/bash.py", line 276, in execute
    raise AirflowException(
airflow.exceptions.AirflowException: Bash command failed. The command returned a non-zero exit code 127.

During handling of the above exception, another exception occurred:

Traceback (most recent call last):
  File "/home/airflow/.local/lib/python3.12/site-packages/airflow/models/taskinstance.py", line 1566, in _run_finished_callback
    callback(context)
  File "/opt/airflow/dags/dag_pipeline.py", line 12, in notify_failure
    send_email(to=['cvsalimoliveira@gmail.com'], subject=subject, html_content=body)  #Please edit it with your email
    ^^^^^^^^^^^^^^^^^^^^^^^^^^^^^^^^^^^^^^^^^^^^^^^^^^^^^^^^^^^^^^^^^^^^^^^^^^^^^^^^
  File "/home/airflow/.local/lib/python3.12/site-packages/airflow/utils/email.py", line 80, in send_email
    return backend(
           ^^^^^^^^
  File "/home/airflow/.local/lib/python3.12/site-packages/airflow/utils/email.py", line 155, in send_email_smtp
    send_mime_email(e_from=mail_from, e_to=recipients, mime_msg=msg, conn_id=conn_id, dryrun=dryrun)
  File "/home/airflow/.local/lib/python3.12/site-packages/airflow/utils/email.py", line 282, in send_mime_email
    smtp_conn.login(smtp_user, smtp_password)
  File "/usr/local/lib/python3.12/smtplib.py", line 750, in login
    raise last_exception
  File "/usr/local/lib/python3.12/smtplib.py", line 739, in login
    (code, resp) = self.auth(
                   ^^^^^^^^^^
  File "/usr/local/lib/python3.12/smtplib.py", line 662, in auth
    raise SMTPAuthenticationError(code, resp)
smtplib.SMTPAuthenticationError: (535, b'5.7.8 Username and Password not accepted. For more information, go to\n5.7.8  https://support.google.com/mail/?p=BadCredentials d9443c01a7336-225c6bd5ccesm103699475ad.258 - gsmtp')
[2025-03-19T03:54:38.232+0000] {taskinstance.py:341} INFO - ::group::Post task execution logs
[2025-03-19T03:54:38.233+0000] {standard_task_runner.py:124} ERROR - Failed to execute job 82 for task bronze_ingestion (Bash command failed. The command returned a non-zero exit code 127.; 420)
Traceback (most recent call last):
  File "/home/airflow/.local/lib/python3.12/site-packages/airflow/task/task_runner/standard_task_runner.py", line 117, in _start_by_fork
    ret = args.func(args, dag=self.dag)
          ^^^^^^^^^^^^^^^^^^^^^^^^^^^^^
  File "/home/airflow/.local/lib/python3.12/site-packages/airflow/cli/cli_config.py", line 49, in command
    return func(*args, **kwargs)
           ^^^^^^^^^^^^^^^^^^^^^
  File "/home/airflow/.local/lib/python3.12/site-packages/airflow/utils/cli.py", line 116, in wrapper
    return f(*args, **kwargs)
           ^^^^^^^^^^^^^^^^^^
  File "/home/airflow/.local/lib/python3.12/site-packages/airflow/cli/commands/task_command.py", line 483, in task_run
    task_return_code = _run_task_by_selected_method(args, _dag, ti)
                       ^^^^^^^^^^^^^^^^^^^^^^^^^^^^^^^^^^^^^^^^^^^^
  File "/home/airflow/.local/lib/python3.12/site-packages/airflow/cli/commands/task_command.py", line 256, in _run_task_by_selected_method
    return _run_raw_task(args, ti)
           ^^^^^^^^^^^^^^^^^^^^^^^
  File "/home/airflow/.local/lib/python3.12/site-packages/airflow/cli/commands/task_command.py", line 341, in _run_raw_task
    return ti._run_raw_task(
           ^^^^^^^^^^^^^^^^^
  File "/home/airflow/.local/lib/python3.12/site-packages/airflow/utils/session.py", line 97, in wrapper
    return func(*args, session=session, **kwargs)
           ^^^^^^^^^^^^^^^^^^^^^^^^^^^^^^^^^^^^^^
  File "/home/airflow/.local/lib/python3.12/site-packages/airflow/models/taskinstance.py", line 3006, in _run_raw_task
    return _run_raw_task(
           ^^^^^^^^^^^^^^
  File "/home/airflow/.local/lib/python3.12/site-packages/airflow/models/taskinstance.py", line 274, in _run_raw_task
    TaskInstance._execute_task_with_callbacks(
  File "/home/airflow/.local/lib/python3.12/site-packages/airflow/models/taskinstance.py", line 3161, in _execute_task_with_callbacks
    result = self._execute_task(context, task_orig)
             ^^^^^^^^^^^^^^^^^^^^^^^^^^^^^^^^^^^^^^
  File "/home/airflow/.local/lib/python3.12/site-packages/airflow/models/taskinstance.py", line 3185, in _execute_task
    return _execute_task(self, context, task_orig)
           ^^^^^^^^^^^^^^^^^^^^^^^^^^^^^^^^^^^^^^^
  File "/home/airflow/.local/lib/python3.12/site-packages/airflow/models/taskinstance.py", line 768, in _execute_task
    result = _execute_callable(context=context, **execute_callable_kwargs)
             ^^^^^^^^^^^^^^^^^^^^^^^^^^^^^^^^^^^^^^^^^^^^^^^^^^^^^^^^^^^^^
  File "/home/airflow/.local/lib/python3.12/site-packages/airflow/models/taskinstance.py", line 734, in _execute_callable
    return ExecutionCallableRunner(
           ^^^^^^^^^^^^^^^^^^^^^^^^
  File "/home/airflow/.local/lib/python3.12/site-packages/airflow/utils/operator_helpers.py", line 252, in run
    return self.func(*args, **kwargs)
           ^^^^^^^^^^^^^^^^^^^^^^^^^^
  File "/home/airflow/.local/lib/python3.12/site-packages/airflow/models/baseoperator.py", line 424, in wrapper
    return func(self, *args, **kwargs)
           ^^^^^^^^^^^^^^^^^^^^^^^^^^^
  File "/home/airflow/.local/lib/python3.12/site-packages/airflow/operators/bash.py", line 276, in execute
    raise AirflowException(
airflow.exceptions.AirflowException: Bash command failed. The command returned a non-zero exit code 127.
[2025-03-19T03:54:38.256+0000] {local_task_job_runner.py:266} INFO - Task exited with return code 1
[2025-03-19T03:54:38.287+0000] {taskinstance.py:3901} INFO - 0 downstream tasks scheduled from follow-on schedule check
[2025-03-19T03:54:38.291+0000] {local_task_job_runner.py:245} INFO - ::endgroup::
