[2025-03-18T22:03:35.650+0000] {local_task_job_runner.py:123} INFO - ::group::Pre task execution logs
[2025-03-18T22:03:35.682+0000] {taskinstance.py:2614} INFO - Dependencies all met for dep_context=non-requeueable deps ti=<TaskInstance: pyspark_etl_pipeline.gold_ingestion manual__2025-03-18T20:56:22.390623+00:00 [queued]>
[2025-03-18T22:03:35.697+0000] {taskinstance.py:2614} INFO - Dependencies all met for dep_context=requeueable deps ti=<TaskInstance: pyspark_etl_pipeline.gold_ingestion manual__2025-03-18T20:56:22.390623+00:00 [queued]>
[2025-03-18T22:03:35.697+0000] {taskinstance.py:2867} INFO - Starting attempt 1 of 2
[2025-03-18T22:03:35.715+0000] {taskinstance.py:2890} INFO - Executing <Task(BashOperator): gold_ingestion> on 2025-03-18 20:56:22.390623+00:00
[2025-03-18T22:03:35.723+0000] {standard_task_runner.py:104} INFO - Running: ['***', 'tasks', 'run', 'pyspark_etl_pipeline', 'gold_ingestion', 'manual__2025-03-18T20:56:22.390623+00:00', '--job-id', '74', '--raw', '--subdir', 'DAGS_FOLDER/dag_pipeline.py', '--cfg-path', '/tmp/tmptejkiyo2']
[2025-03-18T22:03:35.726+0000] {standard_task_runner.py:105} INFO - Job 74: Subtask gold_ingestion
[2025-03-18T22:03:35.728+0000] {logging_mixin.py:190} WARNING - /home/***/.local/lib/python3.12/site-packages/***/task/task_runner/standard_task_runner.py:70 DeprecationWarning: This process (pid=367) is multi-threaded, use of fork() may lead to deadlocks in the child.
[2025-03-18T22:03:35.730+0000] {standard_task_runner.py:72} INFO - Started process 368 to run task
[2025-03-18T22:03:35.786+0000] {task_command.py:467} INFO - Running <TaskInstance: pyspark_etl_pipeline.gold_ingestion manual__2025-03-18T20:56:22.390623+00:00 [running]> on host 5441dd2ef7f9
[2025-03-18T22:03:35.891+0000] {taskinstance.py:3134} INFO - Exporting env vars: AIRFLOW_CTX_DAG_OWNER='***' AIRFLOW_CTX_DAG_ID='pyspark_etl_pipeline' AIRFLOW_CTX_TASK_ID='gold_ingestion' AIRFLOW_CTX_EXECUTION_DATE='2025-03-18T20:56:22.390623+00:00' AIRFLOW_CTX_TRY_NUMBER='1' AIRFLOW_CTX_DAG_RUN_ID='manual__2025-03-18T20:56:22.390623+00:00'
[2025-03-18T22:03:35.892+0000] {taskinstance.py:732} INFO - ::endgroup::
[2025-03-18T22:03:35.931+0000] {subprocess.py:78} INFO - Tmp dir root location: /tmp
[2025-03-18T22:03:35.932+0000] {subprocess.py:88} INFO - Running command: ['/usr/bin/bash', '-c', 'spark-submit --master local /opt/***/dags/gold_ingestion.py']
[2025-03-18T22:03:35.940+0000] {subprocess.py:99} INFO - Output:
[2025-03-18T22:03:35.942+0000] {subprocess.py:106} INFO - /usr/bin/bash: line 1: spark-submit: command not found
[2025-03-18T22:03:35.943+0000] {subprocess.py:110} INFO - Command exited with return code 127
[2025-03-18T22:03:35.956+0000] {taskinstance.py:3313} ERROR - Task failed with exception
Traceback (most recent call last):
  File "/home/airflow/.local/lib/python3.12/site-packages/airflow/models/taskinstance.py", line 768, in _execute_task
    result = _execute_callable(context=context, **execute_callable_kwargs)
             ^^^^^^^^^^^^^^^^^^^^^^^^^^^^^^^^^^^^^^^^^^^^^^^^^^^^^^^^^^^^^
  File "/home/airflow/.local/lib/python3.12/site-packages/airflow/models/taskinstance.py", line 734, in _execute_callable
    return ExecutionCallableRunner(
           ^^^^^^^^^^^^^^^^^^^^^^^^
  File "/home/airflow/.local/lib/python3.12/site-packages/airflow/utils/operator_helpers.py", line 252, in run
    return self.func(*args, **kwargs)
           ^^^^^^^^^^^^^^^^^^^^^^^^^^
  File "/home/airflow/.local/lib/python3.12/site-packages/airflow/models/baseoperator.py", line 424, in wrapper
    return func(self, *args, **kwargs)
           ^^^^^^^^^^^^^^^^^^^^^^^^^^^
  File "/home/airflow/.local/lib/python3.12/site-packages/airflow/operators/bash.py", line 276, in execute
    raise AirflowException(
airflow.exceptions.AirflowException: Bash command failed. The command returned a non-zero exit code 127.
[2025-03-18T22:03:35.966+0000] {taskinstance.py:1226} INFO - Marking task as UP_FOR_RETRY. dag_id=pyspark_etl_pipeline, task_id=gold_ingestion, run_id=manual__2025-03-18T20:56:22.390623+00:00, execution_date=20250318T205622, start_date=20250318T220335, end_date=20250318T220335
[2025-03-18T22:03:36.003+0000] {taskinstance.py:341} INFO - ::group::Post task execution logs
[2025-03-18T22:03:36.004+0000] {standard_task_runner.py:124} ERROR - Failed to execute job 74 for task gold_ingestion (Bash command failed. The command returned a non-zero exit code 127.; 368)
Traceback (most recent call last):
  File "/home/airflow/.local/lib/python3.12/site-packages/airflow/task/task_runner/standard_task_runner.py", line 117, in _start_by_fork
    ret = args.func(args, dag=self.dag)
          ^^^^^^^^^^^^^^^^^^^^^^^^^^^^^
  File "/home/airflow/.local/lib/python3.12/site-packages/airflow/cli/cli_config.py", line 49, in command
    return func(*args, **kwargs)
           ^^^^^^^^^^^^^^^^^^^^^
  File "/home/airflow/.local/lib/python3.12/site-packages/airflow/utils/cli.py", line 116, in wrapper
    return f(*args, **kwargs)
           ^^^^^^^^^^^^^^^^^^
  File "/home/airflow/.local/lib/python3.12/site-packages/airflow/cli/commands/task_command.py", line 483, in task_run
    task_return_code = _run_task_by_selected_method(args, _dag, ti)
                       ^^^^^^^^^^^^^^^^^^^^^^^^^^^^^^^^^^^^^^^^^^^^
  File "/home/airflow/.local/lib/python3.12/site-packages/airflow/cli/commands/task_command.py", line 256, in _run_task_by_selected_method
    return _run_raw_task(args, ti)
           ^^^^^^^^^^^^^^^^^^^^^^^
  File "/home/airflow/.local/lib/python3.12/site-packages/airflow/cli/commands/task_command.py", line 341, in _run_raw_task
    return ti._run_raw_task(
           ^^^^^^^^^^^^^^^^^
  File "/home/airflow/.local/lib/python3.12/site-packages/airflow/utils/session.py", line 97, in wrapper
    return func(*args, session=session, **kwargs)
           ^^^^^^^^^^^^^^^^^^^^^^^^^^^^^^^^^^^^^^
  File "/home/airflow/.local/lib/python3.12/site-packages/airflow/models/taskinstance.py", line 3006, in _run_raw_task
    return _run_raw_task(
           ^^^^^^^^^^^^^^
  File "/home/airflow/.local/lib/python3.12/site-packages/airflow/models/taskinstance.py", line 274, in _run_raw_task
    TaskInstance._execute_task_with_callbacks(
  File "/home/airflow/.local/lib/python3.12/site-packages/airflow/models/taskinstance.py", line 3161, in _execute_task_with_callbacks
    result = self._execute_task(context, task_orig)
             ^^^^^^^^^^^^^^^^^^^^^^^^^^^^^^^^^^^^^^
  File "/home/airflow/.local/lib/python3.12/site-packages/airflow/models/taskinstance.py", line 3185, in _execute_task
    return _execute_task(self, context, task_orig)
           ^^^^^^^^^^^^^^^^^^^^^^^^^^^^^^^^^^^^^^^
  File "/home/airflow/.local/lib/python3.12/site-packages/airflow/models/taskinstance.py", line 768, in _execute_task
    result = _execute_callable(context=context, **execute_callable_kwargs)
             ^^^^^^^^^^^^^^^^^^^^^^^^^^^^^^^^^^^^^^^^^^^^^^^^^^^^^^^^^^^^^
  File "/home/airflow/.local/lib/python3.12/site-packages/airflow/models/taskinstance.py", line 734, in _execute_callable
    return ExecutionCallableRunner(
           ^^^^^^^^^^^^^^^^^^^^^^^^
  File "/home/airflow/.local/lib/python3.12/site-packages/airflow/utils/operator_helpers.py", line 252, in run
    return self.func(*args, **kwargs)
           ^^^^^^^^^^^^^^^^^^^^^^^^^^
  File "/home/airflow/.local/lib/python3.12/site-packages/airflow/models/baseoperator.py", line 424, in wrapper
    return func(self, *args, **kwargs)
           ^^^^^^^^^^^^^^^^^^^^^^^^^^^
  File "/home/airflow/.local/lib/python3.12/site-packages/airflow/operators/bash.py", line 276, in execute
    raise AirflowException(
airflow.exceptions.AirflowException: Bash command failed. The command returned a non-zero exit code 127.
[2025-03-18T22:03:36.037+0000] {local_task_job_runner.py:266} INFO - Task exited with return code 1
[2025-03-18T22:03:36.066+0000] {taskinstance.py:3901} INFO - 0 downstream tasks scheduled from follow-on schedule check
[2025-03-18T22:03:36.068+0000] {local_task_job_runner.py:245} INFO - ::endgroup::
